Workbook
Name dBMI: OFFSET('Daily Tracking'!$M$6,0,0,'Daily Tracking'!$P$2,1)
Name dDates: OFFSET('Daily Tracking'!$A$6,0,0,'Daily Tracking'!$P$2,1)
Name dGoal: OFFSET('Daily Tracking'!$N$6,0,0,'Daily Tracking'!$P$2,1)
Name dMA: OFFSET('Daily Tracking'!$D$6,0,0,'Daily Tracking'!$P$2,1)
Name dWeight: OFFSET('Daily Tracking'!$B$6,0,0,'Daily Tracking'!$P$2,1)
Name mCats: OFFSET('Monthly Analysis'!$A$6,0,0,MAX(1,'Monthly Analysis'!$L$2),1)
Name mLost: OFFSET('Monthly Analysis'!$F$6,0,0,MAX(1,'Monthly Analysis'!$L$2),1)
Name wAvg: OFFSET('Weekly Analysis'!$D$6,0,0,MAX(1,'Weekly Analysis'!$R$2),1)
Name wCats: OFFSET('Weekly Analysis'!$A$6,0,0,MAX(1,'Weekly Analysis'!$R$2),1)
Name wLoss: OFFSET('Weekly Analysis'!$E$6,0,0,MAX(1,'Weekly Analysis'!$R$2),1)

Sheet Read Me
B1: WEIGHT LOSS TRACKER
B2: How this workbook works — read once, then start logging.
B4: 1. START HERE
B5: Settings | C5: Enter your height, start date, start weight, goal weight, age, sex, activity level and daily habit goals. Everything else in the workbook is driven from here.
B6: Daily Tracking | C6: Log one row per day: weight, calories, protein, water, steps, cardio, strength, sleep and a note. Dates are already filled in for 2 years.
B7: Body Measurements | C7: Add waist, chest, arms, thighs and neck every 1–2 weeks. Changes vs your first entry are calculated for you.
B8: Meal & Workout Log | C8: Optional detail behind the daily numbers — individual meals and training sessions.
B10: 2. WHAT CALCULATES ITSELF
B11: Dashboard | C11: Headline numbers, insights and charts. Nothing to type here.
B12: Weekly / Monthly Analysis | C12: Roll-ups of your daily log: average weight, loss per period, averages for calories, protein, steps, sleep and water.
B13: Habit Tracker | C13: Scores six habits per day straight from your Daily Tracking entries — do not type in the grid, it fills itself.
B14: Goal Planner | C14: Required weekly rate, projected finish date and a 12-week projection curve.
B15: Milestones | C15: Every 5 kg from start to goal, with the date you hit it detected automatically.
B16: App Spec | C16: A written specification of this tracker as a mobile app: every field, rule, screen and notification. Hand it to a developer or paste it into an app builder.
B17: 3. COLOUR LEGEND
B18: Type here | C18: Blue figures on a white background are your inputs — the only cells you need to fill in.
B19: Calculated | C19: Grey-shaded columns are formulas. They are locked so they cannot be overwritten by accident.
B20: Good | C20: Green means moving towards your goal (weight down, habit hit).
B21: Off track | C21: Red means moving away from your goal — check your calories and consistency that week.
B22: + − toggle | C22: Some sheets have collapsed helper columns that feed the charts. Click the + above the column letters to see them.
B24: 4. YOUR PLAN AT A GLANCE
B25: Tracking window | C25: =DAY(Settings!$B$4)&" "&TEXT(Settings!$B$4,"mmm")&" "&YEAR(Settings!$B$4)&" to "&DAY('Daily Tracking'!$A$735)&" "&TEXT('Daily Tracking'!$A$735,"mmm")&" "&YEAR('Daily Tracking'!$A$735)&" (730 days)" -> 13 sept 2026 to 11 sept 2028 (730 days)
B26: Start → goal | C26: =FIXED(Settings!$B$5,1)&" kg → "&FIXED(Settings!$B$6,1)&" kg ("&FIXED(Settings!$B$5-Settings!$B$6,1)&" kg to lose)" -> 157,0 kg → 100,0 kg (57,0 kg to lose)
B27: Required pace | C27: =FIXED((Settings!$B$5-Settings!$B$6)/104,2)&" kg per week to finish inside the 2-year window" -> 0,55 kg per week to finish inside the 2-year window
B29: Tip | C29: Weigh yourself at the same time each morning. Day-to-day swings are mostly water — trust the 7-day average and the weekly trend, not a single reading.
B31: Protection | C31: Formula cells are locked so they cannot be typed over. Only the blue input cells accept entries. To change the layout yourself: Review tab > Unprotect Sheet (no password).
B33: Sheets

Sheet Dashboard
A1: WEIGHT LOSS ANALYTICS
A2: ="Goal: "&FIXED(Settings!$B$6,1)&" kg • Started "&DAY(Settings!$B$4)&" "&TEXT(Settings!$B$4,"mmm")&" "&YEAR(Settings!$B$4)&" • Last entry "&DAY($S$8)&" "&TEXT($S$8,"mmm")&" "&YEAR($S$8) -> Goal: 100,0 kg • Started 13 sept 2026 • Last entry 13 sept 2026
S3: =Settings!$B$5 -> 157
A4: STARTING WEIGHT | E4: CURRENT WEIGHT | I4: GOAL WEIGHT | M4: TOTAL LOST | S4: {=IFERROR(LOOKUP(2,1/('Daily Tracking'!$B$6:$B$735<>""),'Daily Tracking'!$B$6:$B$735),Settings!$B$5)} -> 157
A5: =$S$3 -> 157 | E5: =$S$4 -> 157 | I5: =$S$5 -> 100 | M5: =$S$6 -> 0 | S5: =Settings!$B$6 -> 100
S6: =$S$3-$S$4 -> 0
S7: =MAX(0,$S$4-$S$5) -> 57
A8: REMAINING TO GOAL | E8: AVG WEEKLY LOSS | I8: AVG DAILY CHANGE | M8: CURRENT BMI | S8: {=IFERROR(LOOKUP(2,1/('Daily Tracking'!$B$6:$B$735<>""),'Daily Tracking'!$A$6:$A$735),Settings!$B$4)} -> 46278
A9: =$S$7 -> 57 | E9: =$S$10 -> 0 | I9: =-$S$11 -> 0 | M9: =$S$12 -> 49.551824 | S9: =MAX(1,$S$8-Settings!$B$4+1) -> 1
S10: =$S$6/$S$9*7 -> 0
S11: =$S$6/$S$9 -> 0
A12: DAYS SINCE START | E12: GOAL COMPLETION | I12: EST. GOAL DATE | M12: CONSISTENCY (7d) | S12: =$S$4/((Settings!$B$7)/100)^2 -> 49.551824
A13: =$S$9 -> 1 | E13: =$S$13 -> 0 | I13: =IF($S$16="","—",$S$16) -> — | M13: =IF($S$22="","—",$S$22) -> 0.16666667 | S13: =IF($S$3=$S$5,1,MIN(1,MAX(0,$S$6/($S$3-$S$5)))) -> 0
S14: ='Goal Planner'!$M$4 -> 0
S15: ='Goal Planner'!$M$5
A16: BMR — REST BURN | E16: MAINTENANCE (TDEE) | I16: DAILY CALORIE TARGET | M16: BMI CLASS | S16: ='Goal Planner'!$M$6
A17: =Settings!$B$23 -> 2578 | E17: =Settings!$B$24 -> 3545 | I17: =Settings!$B$11 -> 2800 | M17: =IF($S$12<18.5,"Underweight",IF($S$12<25,"Healthy range",IF($S$12<30,"Overweight",IF($S$12<35,"Obesity I",IF($S$12<40,"Obesity II","Obesity III"))))) -> Obesity III | S17: =IFERROR(AVERAGEIFS('Daily Tracking'!$B$6:$B$735,'Daily Tracking'!$A$6:$A$735,">"&$S$8-7,'Daily Tracking'!$A$6:$A$735,"<="&$S$8),"") -> 157
S18: =IFERROR(AVERAGEIFS('Daily Tracking'!$B$6:$B$735,'Daily Tracking'!$A$6:$A$735,">"&$S$8-14,'Daily Tracking'!$A$6:$A$735,"<="&$S$8-7),"")
S19: =IF(OR($S$17="",$S$18=""),"",$S$18-$S$17)
A20: AUTOMATIC INSIGHTS | S20: ='Goal Planner'!$M$7
A21: =IF($S$19="","• Log at least two weeks of weigh-ins to unlock weekly insights.",IF($S$19>=0,"• You lost "&FIXED($S$19,2)&" kg this week — keep it up!","• You gained "&FIXED(-$S$19,2)&" kg this week. One week never defines a journey.")) -> • Log at least two weeks of weigh-ins to unlock weekly insights. | S21: ='Goal Planner'!$M$8
A22: =IF(COUNT('Daily Tracking'!$B$6:$B$735)<3,"• Your loss-rate insight unlocks after a few weigh-ins.",IF($S$14>=0,"• Your weight is not trending down right now — review calories and activity.","• Your average loss rate is "&FIXED(-$S$14*7,2)&" kg/week ("&FIXED(-$S$14,3)&" kg/day).")) -> • Your loss-rate insight unlocks after a few weigh-ins. | S22: =IFERROR(AVERAGEIFS('Habit Tracker'!$H$6:$H$735,'Habit Tracker'!$A$6:$A$735,">"&$S$8-7,'Habit Tracker'!$A$6:$A$735,"<="&$S$8),"") -> 0.16666667
A23: =IF($S$15="","• A goal projection will appear once your trend turns downward.",IF($S$15=0,"• Congratulations — you have reached your goal weight!","• You are projected to reach your goal in about "&FIXED($S$15/7,1)&" weeks ("&DAY($S$16)&" "&TEXT($S$16,"mmm")&" "&YEAR($S$16)&").")) -> • A goal projection will appear once your trend turns downward.
A24: =IF(OR($S$20="",$S$21=""),"• Trend comparison unlocks after ~2 months of data.",IF(ABS($S$20-$S$21)<0.005,"• Your progress is steady compared to last month.",IF($S$20<$S$21,"• Your progress is ACCELERATING compared to last month ("&FIXED(-$S$20*7,2)&" vs "&FIXED(-$S$21*7,2)&" kg/wk).","• Your progress is SLOWING compared to last month ("&FIXED(-$S$20*7,2)&" vs "&FIXED(-$S$21*7,2)&" kg/wk)."))) -> • Trend comparison unlocks after ~2 months of data.
A25: =IF(OR($S$22="",COUNT('Daily Tracking'!$B$6:$B$735)=0),"• Habit data appears here once you start logging.","• Habit consistency over the last 7 days: "&TEXT($S$22,"0%")&".") -> • Habit consistency over the last 7 days: 17%.
A26: PERFORMANCE METRICS
A28: Days logged | E28: =COUNT('Daily Tracking'!$B$6:$B$735) -> 1 | I28: Current 7-day average | M28: {=IFERROR(LOOKUP(2,1/('Daily Tracking'!$D$6:$D$735<>""),'Daily Tracking'!$D$6:$D$735),"")} -> 157
A29: Logging consistency | E29: =IFERROR(COUNT('Daily Tracking'!$B$6:$B$735)/MAX(1,TODAY()-Settings!$B$4+1),"") -> 1 | I29: Trend, last 14 days | M29: =IFERROR(AVERAGEIFS('Daily Tracking'!$B$6:$B$735,'Daily Tracking'!$A$6:$A$735,">="&TODAY()-6,'Daily Tracking'!$A$6:$A$735,"<="&TODAY())-AVERAGEIFS('Daily Tracking'!$B$6:$B$735,'Daily Tracking'!$A$6:$A$735,">="&TODAY()-13,'Daily Tracking'!$A$6:$A$735,"<="&TODAY()-7),"")
A30: Total lost so far | E30: {=IFERROR(Settings!$B$5-LOOKUP(2,1/('Daily Tracking'!$B$6:$B$735<>""),'Daily Tracking'!$B$6:$B$735),"")} -> 0 | I30: Projected weight in 12 weeks | M30: =IFERROR(IF(OR($M$28="",$M$29=""),"",MAX(Settings!$B$6,$M$28+$M$29*12)),"")
A31: Average weekly loss | E31: =IFERROR(AVERAGE('Weekly Analysis'!$E$6:$E$109),"") -> 0 | I31: Weeks to goal at current trend | M31: =IF(OR($M$29="",$M$29>=0,$M$28=""),"",($M$28-Settings!$B$6)/-$M$29)
A32: Average daily calories | E32: =IFERROR(AVERAGE('Daily Tracking'!$E$6:$E$735),"") | I32: Habit score, last 30 days | M32: =IFERROR(AVERAGEIFS('Habit Tracker'!$H$6:$H$735,'Habit Tracker'!$A$6:$A$735,">="&TODAY()-29,'Habit Tracker'!$A$6:$A$735,"<="&TODAY()),"") -> 0.16666667
A33: Average daily steps | E33: =IFERROR(AVERAGE('Daily Tracking'!$H$6:$H$735),"") | I33: Longest logging streak (days) | M33: =IFERROR(MAX('Habit Tracker'!$I$6:$I$735),"") -> 1

Sheet Settings
A1: SETTINGS & PROFILE
A2: Edit the blue values - every sheet, metric and projection updates automatically.
A4: Start Date | B4: 46278
A5: Starting Weight (kg) | B5: 157
A6: Goal Weight (kg) | B6: 100 | C6: First milestone = 10% of starting weight (clinical standard). Change it anytime.
A7: Height (cm) | B7: 178
A8: Age (years) | B8: 22
A9: Sex | B9: Male | C9: Used for the BMR formula - pick from the dropdown.
A10: Activity Level | B10: Lightly Active | C10: Sedentary / Lightly Active / Moderately Active / Very Active / Extremely Active
A11: Daily Calorie Target (kcal) | B11: =MAX(1500,ROUND(($B$24-750)/50,0)*50) -> 2800 | C11: Auto-suggested (maintenance - 750 kcal). Type your own number to override.
A12: Daily Protein Target (g) | B12: =ROUND($B$6*1.2,0) -> 120 | C12: Auto: 1.2 g per kg of goal weight. Overwrite if you prefer.
A13: Daily Water Goal (L) | B13: 3
A14: Daily Step Goal | B14: 8000
A15: Sleep Goal (h) | B15: 7
A17: CALCULATED HEALTH METRICS
A18: Current Weight (auto, kg) | B18: {=IFERROR(LOOKUP(2,1/('Daily Tracking'!$B$6:$B$735<>""),'Daily Tracking'!$B$6:$B$735),$B$5)} -> 157 | C18: Latest weigh-in from the Daily Tracking sheet.
A19: Starting BMI | B19: =$B$5/($B$7/100)^2 -> 49.551824 | C19: Weight / height squared.
A20: Current BMI | B20: =$B$18/($B$7/100)^2 -> 49.551824 | C20: Updates with every weigh-in.
A21: BMI Classification | B21: =IF($B$20<18.5,"Underweight",IF($B$20<25,"Healthy range",IF($B$20<30,"Overweight",IF($B$20<35,"Obesity class I",IF($B$20<40,"Obesity class II","Obesity class III"))))) -> Obesity class III | C21: WHO classification.
A22: Healthy Weight Range | B22: =FIXED(18.5*($B$7/100)^2,1)&" - "&FIXED(24.9*($B$7/100)^2,1)&" kg" -> 58,6 - 78,9 kg | C22: BMI 18.5-24.9 for your height.
A23: BMR - Resting Burn (kcal/day) | B23: =ROUND(10*$B$18+6.25*$B$7-5*$B$8+IF($B$9="Male",5,-161),0) -> 2578 | C23: Mifflin-St Jeor equation; recalculates as your weight drops.
A24: Maintenance - TDEE (kcal/day) | B24: =ROUND($B$23*IF($B$10="Sedentary",1.2,IF($B$10="Lightly Active",1.375,IF($B$10="Moderately Active",1.55,IF($B$10="Very Active",1.725,1.9)))),0) -> 3545 | C24: BMR x activity factor: calories to stay at current weight.
A25: Planned Daily Deficit (kcal) | B25: =$B$24-$B$11 -> 745 | C25: Maintenance minus your calorie target.
A26: Expected Loss at Target | B26: =FIXED($B$25*7/7700,2)&" kg/week" -> 0,68 kg/week | C26: Based on ~7,700 kcal per kg of body fat.
A29: HOW TO USE
A30: 1. Check your profile above - start date, weights, height, age, sex and activity level (blue cells).
A31: 2. Log each day in 'Daily Tracking' - only the white columns need input; everything else is automatic.
A32: 3. Weigh in at the same time each day (ideally mornings) for the cleanest trend line.
A33: 4. The Dashboard, Weekly, Monthly, Habit and Projection sheets fill in as your data accumulates.
A34: 5. Add body measurements every 1-2 weeks in 'Body Measurements'.
A35: 6. Projections need ~2-3 weeks of weigh-ins before they become meaningful.

Sheet Daily Tracking
A1: DAILY TRACKING
A2: Log your day in the white columns. Grey columns calculate themselves. | P2: {=IFERROR(LOOKUP(2,1/($B$6:$B$735<>""),ROW($B$6:$B$735)-5),1)} -> 1
A5: Date | B5: Weight (kg) | C5: Daily Change | D5: 7-Day Avg | E5: Calories | F5: Protein (g) | G5: Water (L) | H5: Steps | I5: Cardio (min) | J5: Strength | K5: Sleep (h) | L5: Notes | M5: BMI | O5: chart: weight | P5: chart: 7d avg | Q5: chart: BMI | R5: Date | S5: Daily Weight | T5: 7-Day Average | U5: Goal
A6: =Settings!$B$4 -> 46278 | B6: 157 | C6: =IF(B6="","",B6-Settings!$B$5) -> 0 | D6: =IF(B6="","",AVERAGE(B6:B6)) -> 157 | M6: =IF(B6="","",B6/((Settings!$B$7)/100)^2) -> 49.551824 | N6: =Settings!$B$6 -> 100 | O6: =IF($B6="",NA(),$B6) -> 157 | P6: =IF($D6="",NA(),$D6) -> 157 | Q6: =IF($M6="",NA(),$M6) -> 49.551824 | R6: =A6 -> 46278 | S6: =IF($B6="",NA(),$B6) -> 157 | T6: =IF($D6="",NA(),$D6) -> 157 | U6: =Settings!$B$6 -> 100
A7: =A6+1 -> 46279 | C7: {=IF(B7="","",B7-IFERROR(LOOKUP(2,1/($B$6:B6<>""),$B$6:B6),Settings!$B$5))} | D7: =IF(B7="","",AVERAGE(B6:B7)) | M7: =IF(B7="","",B7/((Settings!$B$7)/100)^2) | N7: =Settings!$B$6 -> 100 | O7: =IF($B7="",NA(),$B7) -> #N/A | P7: =IF($D7="",NA(),$D7) -> #N/A | Q7: =IF($M7="",NA(),$M7) -> #N/A | R7: =A7 -> 46279 | S7: =IF($B7="",NA(),$B7) -> #N/A | T7: =IF($D7="",NA(),$D7) -> #N/A | U7: =Settings!$B$6 -> 100
A8: =A7+1 -> 46280 | C8: {=IF(B8="","",B8-IFERROR(LOOKUP(2,1/($B$6:B7<>""),$B$6:B7),Settings!$B$5))} | D8: =IF(B8="","",AVERAGE(B6:B8)) | M8: =IF(B8="","",B8/((Settings!$B$7)/100)^2) | N8: =Settings!$B$6 -> 100 | O8: =IF($B8="",NA(),$B8) -> #N/A | P8: =IF($D8="",NA(),$D8) -> #N/A | Q8: =IF($M8="",NA(),$M8) -> #N/A | R8: =A8 -> 46280 | S8: =IF($B8="",NA(),$B8) -> #N/A | T8: =IF($D8="",NA(),$D8) -> #N/A | U8: =Settings!$B$6 -> 100
A9: =A8+1 -> 46281 | C9: {=IF(B9="","",B9-IFERROR(LOOKUP(2,1/($B$6:B8<>""),$B$6:B8),Settings!$B$5))} | D9: =IF(B9="","",AVERAGE(B6:B9)) | M9: =IF(B9="","",B9/((Settings!$B$7)/100)^2) | N9: =Settings!$B$6 -> 100 | O9: =IF($B9="",NA(),$B9) -> #N/A | P9: =IF($D9="",NA(),$D9) -> #N/A | Q9: =IF($M9="",NA(),$M9) -> #N/A | R9: =A9 -> 46281 | S9: =IF($B9="",NA(),$B9) -> #N/A | T9: =IF($D9="",NA(),$D9) -> #N/A | U9: =Settings!$B$6 -> 100
A10: =A9+1 -> 46282 | C10: {=IF(B10="","",B10-IFERROR(LOOKUP(2,1/($B$6:B9<>""),$B$6:B9),Settings!$B$5))} | D10: =IF(B10="","",AVERAGE(B6:B10)) | M10: =IF(B10="","",B10/((Settings!$B$7)/100)^2) | N10: =Settings!$B$6 -> 100 | O10: =IF($B10="",NA(),$B10) -> #N/A | P10: =IF($D10="",NA(),$D10) -> #N/A | Q10: =IF($M10="",NA(),$M10) -> #N/A | R10: =A10 -> 46282 | S10: =IF($B10="",NA(),$B10) -> #N/A | T10: =IF($D10="",NA(),$D10) -> #N/A | U10: =Settings!$B$6 -> 100
A11: =A10+1 -> 46283 | C11: {=IF(B11="","",B11-IFERROR(LOOKUP(2,1/($B$6:B10<>""),$B$6:B10),Settings!$B$5))} | D11: =IF(B11="","",AVERAGE(B6:B11)) | M11: =IF(B11="","",B11/((Settings!$B$7)/100)^2) | N11: =Settings!$B$6 -> 100 | O11: =IF($B11="",NA(),$B11) -> #N/A | P11: =IF($D11="",NA(),$D11) -> #N/A | Q11: =IF($M11="",NA(),$M11) -> #N/A | R11: =A11 -> 46283 | S11: =IF($B11="",NA(),$B11) -> #N/A | T11: =IF($D11="",NA(),$D11) -> #N/A | U11: =Settings!$B$6 -> 100
A12: =A11+1 -> 46284 | C12: {=IF(B12="","",B12-IFERROR(LOOKUP(2,1/($B$6:B11<>""),$B$6:B11),Settings!$B$5))} | D12: =IF(B12="","",AVERAGE(B6:B12)) | M12: =IF(B12="","",B12/((Settings!$B$7)/100)^2) | N12: =Settings!$B$6 -> 100 | O12: =IF($B12="",NA(),$B12) -> #N/A | P12: =IF($D12="",NA(),$D12) -> #N/A | Q12: =IF($M12="",NA(),$M12) -> #N/A | R12: =A12 -> 46284 | S12: =IF($B12="",NA(),$B12) -> #N/A | T12: =IF($D12="",NA(),$D12) -> #N/A | U12: =Settings!$B$6 -> 100
A13: =A12+1 -> 46285 | C13: {=IF(B13="","",B13-IFERROR(LOOKUP(2,1/($B$6:B12<>""),$B$6:B12),Settings!$B$5))} | D13: =IF(B13="","",AVERAGE(B7:B13)) | M13: =IF(B13="","",B13/((Settings!$B$7)/100)^2) | N13: =Settings!$B$6 -> 100 | O13: =IF($B13="",NA(),$B13) -> #N/A | P13: =IF($D13="",NA(),$D13) -> #N/A | Q13: =IF($M13="",NA(),$M13) -> #N/A | R13: =A13 -> 46285 | S13: =IF($B13="",NA(),$B13) -> #N/A | T13: =IF($D13="",NA(),$D13) -> #N/A | U13: =Settings!$B$6 -> 100
A14: =A13+1 -> 46286 | C14: {=IF(B14="","",B14-IFERROR(LOOKUP(2,1/($B$6:B13<>""),$B$6:B13),Settings!$B$5))} | D14: =IF(B14="","",AVERAGE(B8:B14)) | M14: =IF(B14="","",B14/((Settings!$B$7)/100)^2) | N14: =Settings!$B$6 -> 100 | O14: =IF($B14="",NA(),$B14) -> #N/A | P14: =IF($D14="",NA(),$D14) -> #N/A | Q14: =IF($M14="",NA(),$M14) -> #N/A | R14: =A14 -> 46286 | S14: =IF($B14="",NA(),$B14) -> #N/A | T14: =IF($D14="",NA(),$D14) -> #N/A | U14: =Settings!$B$6 -> 100
A15: =A14+1 -> 46287 | C15: {=IF(B15="","",B15-IFERROR(LOOKUP(2,1/($B$6:B14<>""),$B$6:B14),Settings!$B$5))} | D15: =IF(B15="","",AVERAGE(B9:B15)) | M15: =IF(B15="","",B15/((Settings!$B$7)/100)^2) | N15: =Settings!$B$6 -> 100 | O15: =IF($B15="",NA(),$B15) -> #N/A | P15: =IF($D15="",NA(),$D15) -> #N/A | Q15: =IF($M15="",NA(),$M15) -> #N/A | R15: =A15 -> 46287 | S15: =IF($B15="",NA(),$B15) -> #N/A | T15: =IF($D15="",NA(),$D15) -> #N/A | U15: =Settings!$B$6 -> 100
A16: =A15+1 -> 46288 | C16: {=IF(B16="","",B16-IFERROR(LOOKUP(2,1/($B$6:B15<>""),$B$6:B15),Settings!$B$5))} | D16: =IF(B16="","",AVERAGE(B10:B16)) | M16: =IF(B16="","",B16/((Settings!$B$7)/100)^2) | N16: =Settings!$B$6 -> 100 | O16: =IF($B16="",NA(),$B16) -> #N/A | P16: =IF($D16="",NA(),$D16) -> #N/A | Q16: =IF($M16="",NA(),$M16) -> #N/A | R16: =A16 -> 46288 | S16: =IF($B16="",NA(),$B16) -> #N/A | T16: =IF($D16="",NA(),$D16) -> #N/A | U16: =Settings!$B$6 -> 100
A17: =A16+1 -> 46289 | C17: {=IF(B17="","",B17-IFERROR(LOOKUP(2,1/($B$6:B16<>""),$B$6:B16),Settings!$B$5))} | D17: =IF(B17="","",AVERAGE(B11:B17)) | M17: =IF(B17="","",B17/((Settings!$B$7)/100)^2) | N17: =Settings!$B$6 -> 100 | O17: =IF($B17="",NA(),$B17) -> #N/A | P17: =IF($D17="",NA(),$D17) -> #N/A | Q17: =IF($M17="",NA(),$M17) -> #N/A | R17: =A17 -> 46289 | S17: =IF($B17="",NA(),$B17) -> #N/A | T17: =IF($D17="",NA(),$D17) -> #N/A | U17: =Settings!$B$6 -> 100
A18: =A17+1 -> 46290 | C18: {=IF(B18="","",B18-IFERROR(LOOKUP(2,1/($B$6:B17<>""),$B$6:B17),Settings!$B$5))} | D18: =IF(B18="","",AVERAGE(B12:B18)) | M18: =IF(B18="","",B18/((Settings!$B$7)/100)^2) | N18: =Settings!$B$6 -> 100 | O18: =IF($B18="",NA(),$B18) -> #N/A | P18: =IF($D18="",NA(),$D18) -> #N/A | Q18: =IF($M18="",NA(),$M18) -> #N/A | R18: =A18 -> 46290 | S18: =IF($B18="",NA(),$B18) -> #N/A | T18: =IF($D18="",NA(),$D18) -> #N/A | U18: =Settings!$B$6 -> 100
A19: =A18+1 -> 46291 | C19: {=IF(B19="","",B19-IFERROR(LOOKUP(2,1/($B$6:B18<>""),$B$6:B18),Settings!$B$5))} | D19: =IF(B19="","",AVERAGE(B13:B19)) | M19: =IF(B19="","",B19/((Settings!$B$7)/100)^2) | N19: =Settings!$B$6 -> 100 | O19: =IF($B19="",NA(),$B19) -> #N/A | P19: =IF($D19="",NA(),$D19) -> #N/A | Q19: =IF($M19="",NA(),$M19) -> #N/A | R19: =A19 -> 46291 | S19: =IF($B19="",NA(),$B19) -> #N/A | T19: =IF($D19="",NA(),$D19) -> #N/A | U19: =Settings!$B$6 -> 100
A20: =A19+1 -> 46292 | C20: {=IF(B20="","",B20-IFERROR(LOOKUP(2,1/($B$6:B19<>""),$B$6:B19),Settings!$B$5))} | D20: =IF(B20="","",AVERAGE(B14:B20)) | M20: =IF(B20="","",B20/((Settings!$B$7)/100)^2) | N20: =Settings!$B$6 -> 100 | O20: =IF($B20="",NA(),$B20) -> #N/A | P20: =IF($D20="",NA(),$D20) -> #N/A | Q20: =IF($M20="",NA(),$M20) -> #N/A | R20: =A20 -> 46292 | S20: =IF($B20="",NA(),$B20) -> #N/A | T20: =IF($D20="",NA(),$D20) -> #N/A | U20: =Settings!$B$6 -> 100
A21: =A20+1 -> 46293 | C21: {=IF(B21="","",B21-IFERROR(LOOKUP(2,1/($B$6:B20<>""),$B$6:B20),Settings!$B$5))} | D21: =IF(B21="","",AVERAGE(B15:B21)) | M21: =IF(B21="","",B21/((Settings!$B$7)/100)^2) | N21: =Settings!$B$6 -> 100 | O21: =IF($B21="",NA(),$B21) -> #N/A | P21: =IF($D21="",NA(),$D21) -> #N/A | Q21: =IF($M21="",NA(),$M21) -> #N/A | R21: =A21 -> 46293 | S21: =IF($B21="",NA(),$B21) -> #N/A | T21: =IF($D21="",NA(),$D21) -> #N/A | U21: =Settings!$B$6 -> 100
A22: =A21+1 -> 46294 | C22: {=IF(B22="","",B22-IFERROR(LOOKUP(2,1/($B$6:B21<>""),$B$6:B21),Settings!$B$5))} | D22: =IF(B22="","",AVERAGE(B16:B22)) | M22: =IF(B22="","",B22/((Settings!$B$7)/100)^2) | N22: =Settings!$B$6 -> 100 | O22: =IF($B22="",NA(),$B22) -> #N/A | P22: =IF($D22="",NA(),$D22) -> #N/A | Q22: =IF($M22="",NA(),$M22) -> #N/A | R22: =A22 -> 46294 | S22: =IF($B22="",NA(),$B22) -> #N/A | T22: =IF($D22="",NA(),$D22) -> #N/A | U22: =Settings!$B$6 -> 100
A23: =A22+1 -> 46295 | C23: {=IF(B23="","",B23-IFERROR(LOOKUP(2,1/($B$6:B22<>""),$B$6:B22),Settings!$B$5))} | D23: =IF(B23="","",AVERAGE(B17:B23)) | M23: =IF(B23="","",B23/((Settings!$B$7)/100)^2) | N23: =Settings!$B$6 -> 100 | O23: =IF($B23="",NA(),$B23) -> #N/A | P23: =IF($D23="",NA(),$D23) -> #N/A | Q23: =IF($M23="",NA(),$M23) -> #N/A | R23: =A23 -> 46295 | S23: =IF($B23="",NA(),$B23) -> #N/A | T23: =IF($D23="",NA(),$D23) -> #N/A | U23: =Settings!$B$6 -> 100
... A735: =A734+1 -> 47007 | C735: {=IF(B735="","",B735-IFERROR(LOOKUP(2,1/($B$6:B734<>""),$B$6:B734),Settings!$B$5))} | D735: =IF(B735="","",AVERAGE(B729:B735)) | M735: =IF(B735="","",B735/((Settings!$B$7)/100)^2) | N735: =Settings!$B$6 -> 100 | O735: =IF($B735="",NA(),$B735) -> #N/A | P735: =IF($D735="",NA(),$D735) -> #N/A | Q735: =IF($M735="",NA(),$M735) -> #N/A | R735: =A735 -> 47007 | S735: =IF($B735="",NA(),$B735) -> #N/A | T735: =IF($D735="",NA(),$D735) -> #N/A | U735: =Settings!$B$6 -> 100

Sheet Meal & Workout Log
A1: MEAL & WORKOUT LOG
A2: Optional detail behind your daily totals. Log individual meals on the left, training sessions on the right.
A4: MEALS | H4: WORKOUTS
A5: Date | B5: Meal | C5: Food / description | D5: Calories | E5: Protein (g) | F5: Notes | H5: Date | I5: Type | J5: Exercise / session | K5: Duration (min) | L5: Intensity | M5: Calories burned | N5: Notes

Sheet Weekly Analysis
A1: WEEKLY ANALYSIS
A2: Automatic weekly roll-up of your daily log. | R2: =COUNT(D6:D57) -> 1
A5: Week | B5: Start | C5: End | D5: Avg Weight | E5: Lost (kg) | F5: % Change | G5: Avg Calories | H5: Avg Protein | I5: Avg Steps | J5: Avg Sleep | K5: Avg Water | L5: Cardio (min) | M5: Strength Days | N5: Days Logged | P5: HIGHLIGHTS | S5: chart: lost | T5: chart: avg wt
A6: 1 | B6: =Settings!$B$4+(A6-1)*7 -> 46278 | C6: =B6+6 -> 46284 | D6: =IF(N6=0,"",AVERAGEIFS('Daily Tracking'!$B$6:$B$735,'Daily Tracking'!$A$6:$A$735,">="&B6,'Daily Tracking'!$A$6:$A$735,"<="&C6)) -> 157 | E6: =IF(OR(D6="",Settings!$B$5=""),"",Settings!$B$5-D6) -> 0 | F6: =IF(E6="","",E6/Settings!$B$5) -> 0 | G6: =IFERROR(AVERAGEIFS('Daily Tracking'!$E$6:$E$735,'Daily Tracking'!$A$6:$A$735,">="&B6,'Daily Tracking'!$A$6:$A$735,"<="&C6),"") | H6: =IFERROR(AVERAGEIFS('Daily Tracking'!$F$6:$F$735,'Daily Tracking'!$A$6:$A$735,">="&B6,'Daily Tracking'!$A$6:$A$735,"<="&C6),"") | I6: =IFERROR(AVERAGEIFS('Daily Tracking'!$H$6:$H$735,'Daily Tracking'!$A$6:$A$735,">="&B6,'Daily Tracking'!$A$6:$A$735,"<="&C6),"") | J6: =IFERROR(AVERAGEIFS('Daily Tracking'!$K$6:$K$735,'Daily Tracking'!$A$6:$A$735,">="&B6,'Daily Tracking'!$A$6:$A$735,"<="&C6),"") | K6: =IFERROR(AVERAGEIFS('Daily Tracking'!$G$6:$G$735,'Daily Tracking'!$A$6:$A$735,">="&B6,'Daily Tracking'!$A$6:$A$735,"<="&C6),"") | L6: =IF(N6=0,"",SUMIFS('Daily Tracking'!$I$6:$I$735,'Daily Tracking'!$A$6:$A$735,">="&B6,'Daily Tracking'!$A$6:$A$735,"<="&C6)) -> 0 | M6: =IF(N6=0,"",COUNTIFS('Daily Tracking'!$A$6:$A$735,">="&B6,'Daily Tracking'!$A$6:$A$735,"<="&C6,'Daily Tracking'!$J$6:$J$735,"Yes")) -> 0 | N6: =COUNTIFS('Daily Tracking'!$A$6:$A$735,">="&B6,'Daily Tracking'!$A$6:$A$735,"<="&C6,'Daily Tracking'!$B$6:$B$735,"<>") -> 1 | P6: Best week (most lost) | Q6: =IFERROR("Week "&INDEX($A$6:$A$109,MATCH(MAX($E$6:$E$109),$E$6:$E$109,0))&" ("&FIXED(MAX($E$6:$E$109),2)&" kg)","-") -> Week 1 (0,00 kg) | S6: =IF($E6="",NA(),$E6) -> 0 | T6: =IF($D6="",NA(),$D6) -> 157
A7: =A6+1 -> 2 | B7: =Settings!$B$4+(A7-1)*7 -> 46285 | C7: =B7+6 -> 46291 | D7: =IF(N7=0,"",AVERAGEIFS('Daily Tracking'!$B$6:$B$735,'Daily Tracking'!$A$6:$A$735,">="&B7,'Daily Tracking'!$A$6:$A$735,"<="&C7)) | E7: =IF(OR(D7="",D6=""),"",D6-D7) | F7: =IF(E7="","",E7/D6) | G7: =IFERROR(AVERAGEIFS('Daily Tracking'!$E$6:$E$735,'Daily Tracking'!$A$6:$A$735,">="&B7,'Daily Tracking'!$A$6:$A$735,"<="&C7),"") | H7: =IFERROR(AVERAGEIFS('Daily Tracking'!$F$6:$F$735,'Daily Tracking'!$A$6:$A$735,">="&B7,'Daily Tracking'!$A$6:$A$735,"<="&C7),"") | I7: =IFERROR(AVERAGEIFS('Daily Tracking'!$H$6:$H$735,'Daily Tracking'!$A$6:$A$735,">="&B7,'Daily Tracking'!$A$6:$A$735,"<="&C7),"") | J7: =IFERROR(AVERAGEIFS('Daily Tracking'!$K$6:$K$735,'Daily Tracking'!$A$6:$A$735,">="&B7,'Daily Tracking'!$A$6:$A$735,"<="&C7),"") | K7: =IFERROR(AVERAGEIFS('Daily Tracking'!$G$6:$G$735,'Daily Tracking'!$A$6:$A$735,">="&B7,'Daily Tracking'!$A$6:$A$735,"<="&C7),"") | L7: =IF(N7=0,"",SUMIFS('Daily Tracking'!$I$6:$I$735,'Daily Tracking'!$A$6:$A$735,">="&B7,'Daily Tracking'!$A$6:$A$735,"<="&C7)) | M7: =IF(N7=0,"",COUNTIFS('Daily Tracking'!$A$6:$A$735,">="&B7,'Daily Tracking'!$A$6:$A$735,"<="&C7,'Daily Tracking'!$J$6:$J$735,"Yes")) | N7: =COUNTIFS('Daily Tracking'!$A$6:$A$735,">="&B7,'Daily Tracking'!$A$6:$A$735,"<="&C7,'Daily Tracking'!$B$6:$B$735,"<>") -> 0 | P7: Worst week (least lost) | Q7: =IFERROR("Week "&INDEX($A$6:$A$109,MATCH(MIN($E$6:$E$109),$E$6:$E$109,0))&" ("&FIXED(MIN($E$6:$E$109),2)&" kg)","-") -> Week 1 (0,00 kg) | S7: =IF($E7="",NA(),$E7) -> #N/A | T7: =IF($D7="",NA(),$D7) -> #N/A
A8: =A7+1 -> 3 | B8: =Settings!$B$4+(A8-1)*7 -> 46292 | C8: =B8+6 -> 46298 | D8: =IF(N8=0,"",AVERAGEIFS('Daily Tracking'!$B$6:$B$735,'Daily Tracking'!$A$6:$A$735,">="&B8,'Daily Tracking'!$A$6:$A$735,"<="&C8)) | E8: =IF(OR(D8="",D7=""),"",D7-D8) | F8: =IF(E8="","",E8/D7) | G8: =IFERROR(AVERAGEIFS('Daily Tracking'!$E$6:$E$735,'Daily Tracking'!$A$6:$A$735,">="&B8,'Daily Tracking'!$A$6:$A$735,"<="&C8),"") | H8: =IFERROR(AVERAGEIFS('Daily Tracking'!$F$6:$F$735,'Daily Tracking'!$A$6:$A$735,">="&B8,'Daily Tracking'!$A$6:$A$735,"<="&C8),"") | I8: =IFERROR(AVERAGEIFS('Daily Tracking'!$H$6:$H$735,'Daily Tracking'!$A$6:$A$735,">="&B8,'Daily Tracking'!$A$6:$A$735,"<="&C8),"") | J8: =IFERROR(AVERAGEIFS('Daily Tracking'!$K$6:$K$735,'Daily Tracking'!$A$6:$A$735,">="&B8,'Daily Tracking'!$A$6:$A$735,"<="&C8),"") | K8: =IFERROR(AVERAGEIFS('Daily Tracking'!$G$6:$G$735,'Daily Tracking'!$A$6:$A$735,">="&B8,'Daily Tracking'!$A$6:$A$735,"<="&C8),"") | L8: =IF(N8=0,"",SUMIFS('Daily Tracking'!$I$6:$I$735,'Daily Tracking'!$A$6:$A$735,">="&B8,'Daily Tracking'!$A$6:$A$735,"<="&C8)) | M8: =IF(N8=0,"",COUNTIFS('Daily Tracking'!$A$6:$A$735,">="&B8,'Daily Tracking'!$A$6:$A$735,"<="&C8,'Daily Tracking'!$J$6:$J$735,"Yes")) | N8: =COUNTIFS('Daily Tracking'!$A$6:$A$735,">="&B8,'Daily Tracking'!$A$6:$A$735,"<="&C8,'Daily Tracking'!$B$6:$B$735,"<>") -> 0 | P8: Average weekly loss | Q8: =IFERROR(FIXED(AVERAGE($E$6:$E$109),2)&" kg","-") -> 0,00 kg | S8: =IF($E8="",NA(),$E8) -> #N/A | T8: =IF($D8="",NA(),$D8) -> #N/A
A9: =A8+1 -> 4 | B9: =Settings!$B$4+(A9-1)*7 -> 46299 | C9: =B9+6 -> 46305 | D9: =IF(N9=0,"",AVERAGEIFS('Daily Tracking'!$B$6:$B$735,'Daily Tracking'!$A$6:$A$735,">="&B9,'Daily Tracking'!$A$6:$A$735,"<="&C9)) | E9: =IF(OR(D9="",D8=""),"",D8-D9) | F9: =IF(E9="","",E9/D8) | G9: =IFERROR(AVERAGEIFS('Daily Tracking'!$E$6:$E$735,'Daily Tracking'!$A$6:$A$735,">="&B9,'Daily Tracking'!$A$6:$A$735,"<="&C9),"") | H9: =IFERROR(AVERAGEIFS('Daily Tracking'!$F$6:$F$735,'Daily Tracking'!$A$6:$A$735,">="&B9,'Daily Tracking'!$A$6:$A$735,"<="&C9),"") | I9: =IFERROR(AVERAGEIFS('Daily Tracking'!$H$6:$H$735,'Daily Tracking'!$A$6:$A$735,">="&B9,'Daily Tracking'!$A$6:$A$735,"<="&C9),"") | J9: =IFERROR(AVERAGEIFS('Daily Tracking'!$K$6:$K$735,'Daily Tracking'!$A$6:$A$735,">="&B9,'Daily Tracking'!$A$6:$A$735,"<="&C9),"") | K9: =IFERROR(AVERAGEIFS('Daily Tracking'!$G$6:$G$735,'Daily Tracking'!$A$6:$A$735,">="&B9,'Daily Tracking'!$A$6:$A$735,"<="&C9),"") | L9: =IF(N9=0,"",SUMIFS('Daily Tracking'!$I$6:$I$735,'Daily Tracking'!$A$6:$A$735,">="&B9,'Daily Tracking'!$A$6:$A$735,"<="&C9)) | M9: =IF(N9=0,"",COUNTIFS('Daily Tracking'!$A$6:$A$735,">="&B9,'Daily Tracking'!$A$6:$A$735,"<="&C9,'Daily Tracking'!$J$6:$J$735,"Yes")) | N9: =COUNTIFS('Daily Tracking'!$A$6:$A$735,">="&B9,'Daily Tracking'!$A$6:$A$735,"<="&C9,'Daily Tracking'!$B$6:$B$735,"<>") -> 0 | S9: =IF($E9="",NA(),$E9) -> #N/A | T9: =IF($D9="",NA(),$D9) -> #N/A
A10: =A9+1 -> 5 | B10: =Settings!$B$4+(A10-1)*7 -> 46306 | C10: =B10+6 -> 46312 | D10: =IF(N10=0,"",AVERAGEIFS('Daily Tracking'!$B$6:$B$735,'Daily Tracking'!$A$6:$A$735,">="&B10,'Daily Tracking'!$A$6:$A$735,"<="&C10)) | E10: =IF(OR(D10="",D9=""),"",D9-D10) | F10: =IF(E10="","",E10/D9) | G10: =IFERROR(AVERAGEIFS('Daily Tracking'!$E$6:$E$735,'Daily Tracking'!$A$6:$A$735,">="&B10,'Daily Tracking'!$A$6:$A$735,"<="&C10),"") | H10: =IFERROR(AVERAGEIFS('Daily Tracking'!$F$6:$F$735,'Daily Tracking'!$A$6:$A$735,">="&B10,'Daily Tracking'!$A$6:$A$735,"<="&C10),"") | I10: =IFERROR(AVERAGEIFS('Daily Tracking'!$H$6:$H$735,'Daily Tracking'!$A$6:$A$735,">="&B10,'Daily Tracking'!$A$6:$A$735,"<="&C10),"") | J10: =IFERROR(AVERAGEIFS('Daily Tracking'!$K$6:$K$735,'Daily Tracking'!$A$6:$A$735,">="&B10,'Daily Tracking'!$A$6:$A$735,"<="&C10),"") | K10: =IFERROR(AVERAGEIFS('Daily Tracking'!$G$6:$G$735,'Daily Tracking'!$A$6:$A$735,">="&B10,'Daily Tracking'!$A$6:$A$735,"<="&C10),"") | L10: =IF(N10=0,"",SUMIFS('Daily Tracking'!$I$6:$I$735,'Daily Tracking'!$A$6:$A$735,">="&B10,'Daily Tracking'!$A$6:$A$735,"<="&C10)) | M10: =IF(N10=0,"",COUNTIFS('Daily Tracking'!$A$6:$A$735,">="&B10,'Daily Tracking'!$A$6:$A$735,"<="&C10,'Daily Tracking'!$J$6:$J$735,"Yes")) | N10: =COUNTIFS('Daily Tracking'!$A$6:$A$735,">="&B10,'Daily Tracking'!$A$6:$A$735,"<="&C10,'Daily Tracking'!$B$6:$B$735,"<>") -> 0 | S10: =IF($E10="",NA(),$E10) -> #N/A | T10: =IF($D10="",NA(),$D10) -> #N/A
A11: =A10+1 -> 6 | B11: =Settings!$B$4+(A11-1)*7 -> 46313 | C11: =B11+6 -> 46319 | D11: =IF(N11=0,"",AVERAGEIFS('Daily Tracking'!$B$6:$B$735,'Daily Tracking'!$A$6:$A$735,">="&B11,'Daily Tracking'!$A$6:$A$735,"<="&C11)) | E11: =IF(OR(D11="",D10=""),"",D10-D11) | F11: =IF(E11="","",E11/D10) | G11: =IFERROR(AVERAGEIFS('Daily Tracking'!$E$6:$E$735,'Daily Tracking'!$A$6:$A$735,">="&B11,'Daily Tracking'!$A$6:$A$735,"<="&C11),"") | H11: =IFERROR(AVERAGEIFS('Daily Tracking'!$F$6:$F$735,'Daily Tracking'!$A$6:$A$735,">="&B11,'Daily Tracking'!$A$6:$A$735,"<="&C11),"") | I11: =IFERROR(AVERAGEIFS('Daily Tracking'!$H$6:$H$735,'Daily Tracking'!$A$6:$A$735,">="&B11,'Daily Tracking'!$A$6:$A$735,"<="&C11),"") | J11: =IFERROR(AVERAGEIFS('Daily Tracking'!$K$6:$K$735,'Daily Tracking'!$A$6:$A$735,">="&B11,'Daily Tracking'!$A$6:$A$735,"<="&C11),"") | K11: =IFERROR(AVERAGEIFS('Daily Tracking'!$G$6:$G$735,'Daily Tracking'!$A$6:$A$735,">="&B11,'Daily Tracking'!$A$6:$A$735,"<="&C11),"") | L11: =IF(N11=0,"",SUMIFS('Daily Tracking'!$I$6:$I$735,'Daily Tracking'!$A$6:$A$735,">="&B11,'Daily Tracking'!$A$6:$A$735,"<="&C11)) | M11: =IF(N11=0,"",COUNTIFS('Daily Tracking'!$A$6:$A$735,">="&B11,'Daily Tracking'!$A$6:$A$735,"<="&C11,'Daily Tracking'!$J$6:$J$735,"Yes")) | N11: =COUNTIFS('Daily Tracking'!$A$6:$A$735,">="&B11,'Daily Tracking'!$A$6:$A$735,"<="&C11,'Daily Tracking'!$B$6:$B$735,"<>") -> 0 | S11: =IF($E11="",NA(),$E11) -> #N/A | T11: =IF($D11="",NA(),$D11) -> #N/A
A12: =A11+1 -> 7 | B12: =Settings!$B$4+(A12-1)*7 -> 46320 | C12: =B12+6 -> 46326 | D12: =IF(N12=0,"",AVERAGEIFS('Daily Tracking'!$B$6:$B$735,'Daily Tracking'!$A$6:$A$735,">="&B12,'Daily Tracking'!$A$6:$A$735,"<="&C12)) | E12: =IF(OR(D12="",D11=""),"",D11-D12) | F12: =IF(E12="","",E12/D11) | G12: =IFERROR(AVERAGEIFS('Daily Tracking'!$E$6:$E$735,'Daily Tracking'!$A$6:$A$735,">="&B12,'Daily Tracking'!$A$6:$A$735,"<="&C12),"") | H12: =IFERROR(AVERAGEIFS('Daily Tracking'!$F$6:$F$735,'Daily Tracking'!$A$6:$A$735,">="&B12,'Daily Tracking'!$A$6:$A$735,"<="&C12),"") | I12: =IFERROR(AVERAGEIFS('Daily Tracking'!$H$6:$H$735,'Daily Tracking'!$A$6:$A$735,">="&B12,'Daily Tracking'!$A$6:$A$735,"<="&C12),"") | J12: =IFERROR(AVERAGEIFS('Daily Tracking'!$K$6:$K$735,'Daily Tracking'!$A$6:$A$735,">="&B12,'Daily Tracking'!$A$6:$A$735,"<="&C12),"") | K12: =IFERROR(AVERAGEIFS('Daily Tracking'!$G$6:$G$735,'Daily Tracking'!$A$6:$A$735,">="&B12,'Daily Tracking'!$A$6:$A$735,"<="&C12),"") | L12: =IF(N12=0,"",SUMIFS('Daily Tracking'!$I$6:$I$735,'Daily Tracking'!$A$6:$A$735,">="&B12,'Daily Tracking'!$A$6:$A$735,"<="&C12)) | M12: =IF(N12=0,"",COUNTIFS('Daily Tracking'!$A$6:$A$735,">="&B12,'Daily Tracking'!$A$6:$A$735,"<="&C12,'Daily Tracking'!$J$6:$J$735,"Yes")) | N12: =COUNTIFS('Daily Tracking'!$A$6:$A$735,">="&B12,'Daily Tracking'!$A$6:$A$735,"<="&C12,'Daily Tracking'!$B$6:$B$735,"<>") -> 0 | S12: =IF($E12="",NA(),$E12) -> #N/A | T12: =IF($D12="",NA(),$D12) -> #N/A
A13: =A12+1 -> 8 | B13: =Settings!$B$4+(A13-1)*7 -> 46327 | C13: =B13+6 -> 46333 | D13: =IF(N13=0,"",AVERAGEIFS('Daily Tracking'!$B$6:$B$735,'Daily Tracking'!$A$6:$A$735,">="&B13,'Daily Tracking'!$A$6:$A$735,"<="&C13)) | E13: =IF(OR(D13="",D12=""),"",D12-D13) | F13: =IF(E13="","",E13/D12) | G13: =IFERROR(AVERAGEIFS('Daily Tracking'!$E$6:$E$735,'Daily Tracking'!$A$6:$A$735,">="&B13,'Daily Tracking'!$A$6:$A$735,"<="&C13),"") | H13: =IFERROR(AVERAGEIFS('Daily Tracking'!$F$6:$F$735,'Daily Tracking'!$A$6:$A$735,">="&B13,'Daily Tracking'!$A$6:$A$735,"<="&C13),"") | I13: =IFERROR(AVERAGEIFS('Daily Tracking'!$H$6:$H$735,'Daily Tracking'!$A$6:$A$735,">="&B13,'Daily Tracking'!$A$6:$A$735,"<="&C13),"") | J13: =IFERROR(AVERAGEIFS('Daily Tracking'!$K$6:$K$735,'Daily Tracking'!$A$6:$A$735,">="&B13,'Daily Tracking'!$A$6:$A$735,"<="&C13),"") | K13: =IFERROR(AVERAGEIFS('Daily Tracking'!$G$6:$G$735,'Daily Tracking'!$A$6:$A$735,">="&B13,'Daily Tracking'!$A$6:$A$735,"<="&C13),"") | L13: =IF(N13=0,"",SUMIFS('Daily Tracking'!$I$6:$I$735,'Daily Tracking'!$A$6:$A$735,">="&B13,'Daily Tracking'!$A$6:$A$735,"<="&C13)) | M13: =IF(N13=0,"",COUNTIFS('Daily Tracking'!$A$6:$A$735,">="&B13,'Daily Tracking'!$A$6:$A$735,"<="&C13,'Daily Tracking'!$J$6:$J$735,"Yes")) | N13: =COUNTIFS('Daily Tracking'!$A$6:$A$735,">="&B13,'Daily Tracking'!$A$6:$A$735,"<="&C13,'Daily Tracking'!$B$6:$B$735,"<>") -> 0 | S13: =IF($E13="",NA(),$E13) -> #N/A | T13: =IF($D13="",NA(),$D13) -> #N/A
A14: =A13+1 -> 9 | B14: =Settings!$B$4+(A14-1)*7 -> 46334 | C14: =B14+6 -> 46340 | D14: =IF(N14=0,"",AVERAGEIFS('Daily Tracking'!$B$6:$B$735,'Daily Tracking'!$A$6:$A$735,">="&B14,'Daily Tracking'!$A$6:$A$735,"<="&C14)) | E14: =IF(OR(D14="",D13=""),"",D13-D14) | F14: =IF(E14="","",E14/D13) | G14: =IFERROR(AVERAGEIFS('Daily Tracking'!$E$6:$E$735,'Daily Tracking'!$A$6:$A$735,">="&B14,'Daily Tracking'!$A$6:$A$735,"<="&C14),"") | H14: =IFERROR(AVERAGEIFS('Daily Tracking'!$F$6:$F$735,'Daily Tracking'!$A$6:$A$735,">="&B14,'Daily Tracking'!$A$6:$A$735,"<="&C14),"") | I14: =IFERROR(AVERAGEIFS('Daily Tracking'!$H$6:$H$735,'Daily Tracking'!$A$6:$A$735,">="&B14,'Daily Tracking'!$A$6:$A$735,"<="&C14),"") | J14: =IFERROR(AVERAGEIFS('Daily Tracking'!$K$6:$K$735,'Daily Tracking'!$A$6:$A$735,">="&B14,'Daily Tracking'!$A$6:$A$735,"<="&C14),"") | K14: =IFERROR(AVERAGEIFS('Daily Tracking'!$G$6:$G$735,'Daily Tracking'!$A$6:$A$735,">="&B14,'Daily Tracking'!$A$6:$A$735,"<="&C14),"") | L14: =IF(N14=0,"",SUMIFS('Daily Tracking'!$I$6:$I$735,'Daily Tracking'!$A$6:$A$735,">="&B14,'Daily Tracking'!$A$6:$A$735,"<="&C14)) | M14: =IF(N14=0,"",COUNTIFS('Daily Tracking'!$A$6:$A$735,">="&B14,'Daily Tracking'!$A$6:$A$735,"<="&C14,'Daily Tracking'!$J$6:$J$735,"Yes")) | N14: =COUNTIFS('Daily Tracking'!$A$6:$A$735,">="&B14,'Daily Tracking'!$A$6:$A$735,"<="&C14,'Daily Tracking'!$B$6:$B$735,"<>") -> 0 | S14: =IF($E14="",NA(),$E14) -> #N/A | T14: =IF($D14="",NA(),$D14) -> #N/A
A15: =A14+1 -> 10 | B15: =Settings!$B$4+(A15-1)*7 -> 46341 | C15: =B15+6 -> 46347 | D15: =IF(N15=0,"",AVERAGEIFS('Daily Tracking'!$B$6:$B$735,'Daily Tracking'!$A$6:$A$735,">="&B15,'Daily Tracking'!$A$6:$A$735,"<="&C15)) | E15: =IF(OR(D15="",D14=""),"",D14-D15) | F15: =IF(E15="","",E15/D14) | G15: =IFERROR(AVERAGEIFS('Daily Tracking'!$E$6:$E$735,'Daily Tracking'!$A$6:$A$735,">="&B15,'Daily Tracking'!$A$6:$A$735,"<="&C15),"") | H15: =IFERROR(AVERAGEIFS('Daily Tracking'!$F$6:$F$735,'Daily Tracking'!$A$6:$A$735,">="&B15,'Daily Tracking'!$A$6:$A$735,"<="&C15),"") | I15: =IFERROR(AVERAGEIFS('Daily Tracking'!$H$6:$H$735,'Daily Tracking'!$A$6:$A$735,">="&B15,'Daily Tracking'!$A$6:$A$735,"<="&C15),"") | J15: =IFERROR(AVERAGEIFS('Daily Tracking'!$K$6:$K$735,'Daily Tracking'!$A$6:$A$735,">="&B15,'Daily Tracking'!$A$6:$A$735,"<="&C15),"") | K15: =IFERROR(AVERAGEIFS('Daily Tracking'!$G$6:$G$735,'Daily Tracking'!$A$6:$A$735,">="&B15,'Daily Tracking'!$A$6:$A$735,"<="&C15),"") | L15: =IF(N15=0,"",SUMIFS('Daily Tracking'!$I$6:$I$735,'Daily Tracking'!$A$6:$A$735,">="&B15,'Daily Tracking'!$A$6:$A$735,"<="&C15)) | M15: =IF(N15=0,"",COUNTIFS('Daily Tracking'!$A$6:$A$735,">="&B15,'Daily Tracking'!$A$6:$A$735,"<="&C15,'Daily Tracking'!$J$6:$J$735,"Yes")) | N15: =COUNTIFS('Daily Tracking'!$A$6:$A$735,">="&B15,'Daily Tracking'!$A$6:$A$735,"<="&C15,'Daily Tracking'!$B$6:$B$735,"<>") -> 0 | S15: =IF($E15="",NA(),$E15) -> #N/A | T15: =IF($D15="",NA(),$D15) -> #N/A
A16: =A15+1 -> 11 | B16: =Settings!$B$4+(A16-1)*7 -> 46348 | C16: =B16+6 -> 46354 | D16: =IF(N16=0,"",AVERAGEIFS('Daily Tracking'!$B$6:$B$735,'Daily Tracking'!$A$6:$A$735,">="&B16,'Daily Tracking'!$A$6:$A$735,"<="&C16)) | E16: =IF(OR(D16="",D15=""),"",D15-D16) | F16: =IF(E16="","",E16/D15) | G16: =IFERROR(AVERAGEIFS('Daily Tracking'!$E$6:$E$735,'Daily Tracking'!$A$6:$A$735,">="&B16,'Daily Tracking'!$A$6:$A$735,"<="&C16),"") | H16: =IFERROR(AVERAGEIFS('Daily Tracking'!$F$6:$F$735,'Daily Tracking'!$A$6:$A$735,">="&B16,'Daily Tracking'!$A$6:$A$735,"<="&C16),"") | I16: =IFERROR(AVERAGEIFS('Daily Tracking'!$H$6:$H$735,'Daily Tracking'!$A$6:$A$735,">="&B16,'Daily Tracking'!$A$6:$A$735,"<="&C16),"") | J16: =IFERROR(AVERAGEIFS('Daily Tracking'!$K$6:$K$735,'Daily Tracking'!$A$6:$A$735,">="&B16,'Daily Tracking'!$A$6:$A$735,"<="&C16),"") | K16: =IFERROR(AVERAGEIFS('Daily Tracking'!$G$6:$G$735,'Daily Tracking'!$A$6:$A$735,">="&B16,'Daily Tracking'!$A$6:$A$735,"<="&C16),"") | L16: =IF(N16=0,"",SUMIFS('Daily Tracking'!$I$6:$I$735,'Daily Tracking'!$A$6:$A$735,">="&B16,'Daily Tracking'!$A$6:$A$735,"<="&C16)) | M16: =IF(N16=0,"",COUNTIFS('Daily Tracking'!$A$6:$A$735,">="&B16,'Daily Tracking'!$A$6:$A$735,"<="&C16,'Daily Tracking'!$J$6:$J$735,"Yes")) | N16: =COUNTIFS('Daily Tracking'!$A$6:$A$735,">="&B16,'Daily Tracking'!$A$6:$A$735,"<="&C16,'Daily Tracking'!$B$6:$B$735,"<>") -> 0 | S16: =IF($E16="",NA(),$E16) -> #N/A | T16: =IF($D16="",NA(),$D16) -> #N/A
A17: =A16+1 -> 12 | B17: =Settings!$B$4+(A17-1)*7 -> 46355 | C17: =B17+6 -> 46361 | D17: =IF(N17=0,"",AVERAGEIFS('Daily Tracking'!$B$6:$B$735,'Daily Tracking'!$A$6:$A$735,">="&B17,'Daily Tracking'!$A$6:$A$735,"<="&C17)) | E17: =IF(OR(D17="",D16=""),"",D16-D17) | F17: =IF(E17="","",E17/D16) | G17: =IFERROR(AVERAGEIFS('Daily Tracking'!$E$6:$E$735,'Daily Tracking'!$A$6:$A$735,">="&B17,'Daily Tracking'!$A$6:$A$735,"<="&C17),"") | H17: =IFERROR(AVERAGEIFS('Daily Tracking'!$F$6:$F$735,'Daily Tracking'!$A$6:$A$735,">="&B17,'Daily Tracking'!$A$6:$A$735,"<="&C17),"") | I17: =IFERROR(AVERAGEIFS('Daily Tracking'!$H$6:$H$735,'Daily Tracking'!$A$6:$A$735,">="&B17,'Daily Tracking'!$A$6:$A$735,"<="&C17),"") | J17: =IFERROR(AVERAGEIFS('Daily Tracking'!$K$6:$K$735,'Daily Tracking'!$A$6:$A$735,">="&B17,'Daily Tracking'!$A$6:$A$735,"<="&C17),"") | K17: =IFERROR(AVERAGEIFS('Daily Tracking'!$G$6:$G$735,'Daily Tracking'!$A$6:$A$735,">="&B17,'Daily Tracking'!$A$6:$A$735,"<="&C17),"") | L17: =IF(N17=0,"",SUMIFS('Daily Tracking'!$I$6:$I$735,'Daily Tracking'!$A$6:$A$735,">="&B17,'Daily Tracking'!$A$6:$A$735,"<="&C17)) | M17: =IF(N17=0,"",COUNTIFS('Daily Tracking'!$A$6:$A$735,">="&B17,'Daily Tracking'!$A$6:$A$735,"<="&C17,'Daily Tracking'!$J$6:$J$735,"Yes")) | N17: =COUNTIFS('Daily Tracking'!$A$6:$A$735,">="&B17,'Daily Tracking'!$A$6:$A$735,"<="&C17,'Daily Tracking'!$B$6:$B$735,"<>") -> 0 | S17: =IF($E17="",NA(),$E17) -> #N/A | T17: =IF($D17="",NA(),$D17) -> #N/A
A18: =A17+1 -> 13 | B18: =Settings!$B$4+(A18-1)*7 -> 46362 | C18: =B18+6 -> 46368 | D18: =IF(N18=0,"",AVERAGEIFS('Daily Tracking'!$B$6:$B$735,'Daily Tracking'!$A$6:$A$735,">="&B18,'Daily Tracking'!$A$6:$A$735,"<="&C18)) | E18: =IF(OR(D18="",D17=""),"",D17-D18) | F18: =IF(E18="","",E18/D17) | G18: =IFERROR(AVERAGEIFS('Daily Tracking'!$E$6:$E$735,'Daily Tracking'!$A$6:$A$735,">="&B18,'Daily Tracking'!$A$6:$A$735,"<="&C18),"") | H18: =IFERROR(AVERAGEIFS('Daily Tracking'!$F$6:$F$735,'Daily Tracking'!$A$6:$A$735,">="&B18,'Daily Tracking'!$A$6:$A$735,"<="&C18),"") | I18: =IFERROR(AVERAGEIFS('Daily Tracking'!$H$6:$H$735,'Daily Tracking'!$A$6:$A$735,">="&B18,'Daily Tracking'!$A$6:$A$735,"<="&C18),"") | J18: =IFERROR(AVERAGEIFS('Daily Tracking'!$K$6:$K$735,'Daily Tracking'!$A$6:$A$735,">="&B18,'Daily Tracking'!$A$6:$A$735,"<="&C18),"") | K18: =IFERROR(AVERAGEIFS('Daily Tracking'!$G$6:$G$735,'Daily Tracking'!$A$6:$A$735,">="&B18,'Daily Tracking'!$A$6:$A$735,"<="&C18),"") | L18: =IF(N18=0,"",SUMIFS('Daily Tracking'!$I$6:$I$735,'Daily Tracking'!$A$6:$A$735,">="&B18,'Daily Tracking'!$A$6:$A$735,"<="&C18)) | M18: =IF(N18=0,"",COUNTIFS('Daily Tracking'!$A$6:$A$735,">="&B18,'Daily Tracking'!$A$6:$A$735,"<="&C18,'Daily Tracking'!$J$6:$J$735,"Yes")) | N18: =COUNTIFS('Daily Tracking'!$A$6:$A$735,">="&B18,'Daily Tracking'!$A$6:$A$735,"<="&C18,'Daily Tracking'!$B$6:$B$735,"<>") -> 0 | S18: =IF($E18="",NA(),$E18) -> #N/A | T18: =IF($D18="",NA(),$D18) -> #N/A
A19: =A18+1 -> 14 | B19: =Settings!$B$4+(A19-1)*7 -> 46369 | C19: =B19+6 -> 46375 | D19: =IF(N19=0,"",AVERAGEIFS('Daily Tracking'!$B$6:$B$735,'Daily Tracking'!$A$6:$A$735,">="&B19,'Daily Tracking'!$A$6:$A$735,"<="&C19)) | E19: =IF(OR(D19="",D18=""),"",D18-D19) | F19: =IF(E19="","",E19/D18) | G19: =IFERROR(AVERAGEIFS('Daily Tracking'!$E$6:$E$735,'Daily Tracking'!$A$6:$A$735,">="&B19,'Daily Tracking'!$A$6:$A$735,"<="&C19),"") | H19: =IFERROR(AVERAGEIFS('Daily Tracking'!$F$6:$F$735,'Daily Tracking'!$A$6:$A$735,">="&B19,'Daily Tracking'!$A$6:$A$735,"<="&C19),"") | I19: =IFERROR(AVERAGEIFS('Daily Tracking'!$H$6:$H$735,'Daily Tracking'!$A$6:$A$735,">="&B19,'Daily Tracking'!$A$6:$A$735,"<="&C19),"") | J19: =IFERROR(AVERAGEIFS('Daily Tracking'!$K$6:$K$735,'Daily Tracking'!$A$6:$A$735,">="&B19,'Daily Tracking'!$A$6:$A$735,"<="&C19),"") | K19: =IFERROR(AVERAGEIFS('Daily Tracking'!$G$6:$G$735,'Daily Tracking'!$A$6:$A$735,">="&B19,'Daily Tracking'!$A$6:$A$735,"<="&C19),"") | L19: =IF(N19=0,"",SUMIFS('Daily Tracking'!$I$6:$I$735,'Daily Tracking'!$A$6:$A$735,">="&B19,'Daily Tracking'!$A$6:$A$735,"<="&C19)) | M19: =IF(N19=0,"",COUNTIFS('Daily Tracking'!$A$6:$A$735,">="&B19,'Daily Tracking'!$A$6:$A$735,"<="&C19,'Daily Tracking'!$J$6:$J$735,"Yes")) | N19: =COUNTIFS('Daily Tracking'!$A$6:$A$735,">="&B19,'Daily Tracking'!$A$6:$A$735,"<="&C19,'Daily Tracking'!$B$6:$B$735,"<>") -> 0 | S19: =IF($E19="",NA(),$E19) -> #N/A | T19: =IF($D19="",NA(),$D19) -> #N/A
A20: =A19+1 -> 15 | B20: =Settings!$B$4+(A20-1)*7 -> 46376 | C20: =B20+6 -> 46382 | D20: =IF(N20=0,"",AVERAGEIFS('Daily Tracking'!$B$6:$B$735,'Daily Tracking'!$A$6:$A$735,">="&B20,'Daily Tracking'!$A$6:$A$735,"<="&C20)) | E20: =IF(OR(D20="",D19=""),"",D19-D20) | F20: =IF(E20="","",E20/D19) | G20: =IFERROR(AVERAGEIFS('Daily Tracking'!$E$6:$E$735,'Daily Tracking'!$A$6:$A$735,">="&B20,'Daily Tracking'!$A$6:$A$735,"<="&C20),"") | H20: =IFERROR(AVERAGEIFS('Daily Tracking'!$F$6:$F$735,'Daily Tracking'!$A$6:$A$735,">="&B20,'Daily Tracking'!$A$6:$A$735,"<="&C20),"") | I20: =IFERROR(AVERAGEIFS('Daily Tracking'!$H$6:$H$735,'Daily Tracking'!$A$6:$A$735,">="&B20,'Daily Tracking'!$A$6:$A$735,"<="&C20),"") | J20: =IFERROR(AVERAGEIFS('Daily Tracking'!$K$6:$K$735,'Daily Tracking'!$A$6:$A$735,">="&B20,'Daily Tracking'!$A$6:$A$735,"<="&C20),"") | K20: =IFERROR(AVERAGEIFS('Daily Tracking'!$G$6:$G$735,'Daily Tracking'!$A$6:$A$735,">="&B20,'Daily Tracking'!$A$6:$A$735,"<="&C20),"") | L20: =IF(N20=0,"",SUMIFS('Daily Tracking'!$I$6:$I$735,'Daily Tracking'!$A$6:$A$735,">="&B20,'Daily Tracking'!$A$6:$A$735,"<="&C20)) | M20: =IF(N20=0,"",COUNTIFS('Daily Tracking'!$A$6:$A$735,">="&B20,'Daily Tracking'!$A$6:$A$735,"<="&C20,'Daily Tracking'!$J$6:$J$735,"Yes")) | N20: =COUNTIFS('Daily Tracking'!$A$6:$A$735,">="&B20,'Daily Tracking'!$A$6:$A$735,"<="&C20,'Daily Tracking'!$B$6:$B$735,"<>") -> 0 | S20: =IF($E20="",NA(),$E20) -> #N/A | T20: =IF($D20="",NA(),$D20) -> #N/A
... A109: =A108+1 -> 104 | B109: =Settings!$B$4+(A109-1)*7 -> 46999 | C109: =B109+6 -> 47005 | D109: =IF(N109=0,"",AVERAGEIFS('Daily Tracking'!$B$6:$B$735,'Daily Tracking'!$A$6:$A$735,">="&B109,'Daily Tracking'!$A$6:$A$735,"<="&C109)) | E109: =IF(OR(D109="",D108=""),"",D108-D109) | F109: =IF(E109="","",E109/D108) | G109: =IFERROR(AVERAGEIFS('Daily Tracking'!$E$6:$E$735,'Daily Tracking'!$A$6:$A$735,">="&B109,'Daily Tracking'!$A$6:$A$735,"<="&C109),"") | H109: =IFERROR(AVERAGEIFS('Daily Tracking'!$F$6:$F$735,'Daily Tracking'!$A$6:$A$735,">="&B109,'Daily Tracking'!$A$6:$A$735,"<="&C109),"") | I109: =IFERROR(AVERAGEIFS('Daily Tracking'!$H$6:$H$735,'Daily Tracking'!$A$6:$A$735,">="&B109,'Daily Tracking'!$A$6:$A$735,"<="&C109),"") | J109: =IFERROR(AVERAGEIFS('Daily Tracking'!$K$6:$K$735,'Daily Tracking'!$A$6:$A$735,">="&B109,'Daily Tracking'!$A$6:$A$735,"<="&C109),"") | K109: =IFERROR(AVERAGEIFS('Daily Tracking'!$G$6:$G$735,'Daily Tracking'!$A$6:$A$735,">="&B109,'Daily Tracking'!$A$6:$A$735,"<="&C109),"") | L109: =IF(N109=0,"",SUMIFS('Daily Tracking'!$I$6:$I$735,'Daily Tracking'!$A$6:$A$735,">="&B109,'Daily Tracking'!$A$6:$A$735,"<="&C109)) | M109: =IF(N109=0,"",COUNTIFS('Daily Tracking'!$A$6:$A$735,">="&B109,'Daily Tracking'!$A$6:$A$735,"<="&C109,'Daily Tracking'!$J$6:$J$735,"Yes")) | N109: =COUNTIFS('Daily Tracking'!$A$6:$A$735,">="&B109,'Daily Tracking'!$A$6:$A$735,"<="&C109,'Daily Tracking'!$B$6:$B$735,"<>") -> 0 | S109: =IF($E109="",NA(),$E109) -> #N/A | T109: =IF($D109="",NA(),$D109) -> #N/A

Sheet Monthly Analysis
A1: MONTHLY ANALYSIS
A2: Month-over-month performance comparison. | L2: =COUNT(F6:F17) -> 1
A5: Month | B5: From | C5: To | D5: Start Weight | E5: End Weight | F5: Lost (kg) | G5: % Lost | H5: Avg Daily Loss | I5: Avg Weekly Loss | J5: Days Logged | L5: chart: lost
A6: =TEXT(B6,"mmm")&" "&YEAR(B6) -> sept 2026 | B6: =Settings!$B$4 -> 46278 | C6: =EOMONTH(B6,0) -> 46295 | D6: {=IF(J6=0,"",IFERROR(INDEX('Daily Tracking'!$B$6:$B$735,MATCH(1,INDEX((('Daily Tracking'!$A$6:$A$735>=B6)*('Daily Tracking'!$A$6:$A$735<=C6)*('Daily Tracking'!$B$6:$B$735<>"")),0),0)),""))} -> 157 | E6: {=IF(J6=0,"",IFERROR(LOOKUP(2,1/(('Daily Tracking'!$A$6:$A$735>=B6)*('Daily Tracking'!$A$6:$A$735<=C6)*('Daily Tracking'!$B$6:$B$735<>"")),'Daily Tracking'!$B$6:$B$735),""))} -> 157 | F6: =IF(OR(D6="",E6=""),"",D6-E6) -> 0 | G6: =IF(F6="","",F6/D6) -> 0 | H6: =IF(OR(F6="",J6=0),"",F6/J6) -> 0 | I6: =IF(H6="","",H6*7) -> 0 | J6: =COUNTIFS('Daily Tracking'!$A$6:$A$735,">="&B6,'Daily Tracking'!$A$6:$A$735,"<="&C6,'Daily Tracking'!$B$6:$B$735,"<>") -> 1 | L6: =IF($F6="",NA(),$F6) -> 0
A7: =TEXT(B7,"mmm")&" "&YEAR(B7) -> oct 2026 | B7: =EOMONTH(B6,0)+1 -> 46296 | C7: =EOMONTH(B7,0) -> 46326 | D7: {=IF(J7=0,"",IFERROR(INDEX('Daily Tracking'!$B$6:$B$735,MATCH(1,INDEX((('Daily Tracking'!$A$6:$A$735>=B7)*('Daily Tracking'!$A$6:$A$735<=C7)*('Daily Tracking'!$B$6:$B$735<>"")),0),0)),""))} | E7: {=IF(J7=0,"",IFERROR(LOOKUP(2,1/(('Daily Tracking'!$A$6:$A$735>=B7)*('Daily Tracking'!$A$6:$A$735<=C7)*('Daily Tracking'!$B$6:$B$735<>"")),'Daily Tracking'!$B$6:$B$735),""))} | F7: =IF(OR(D7="",E7=""),"",D7-E7) | G7: =IF(F7="","",F7/D7) | H7: =IF(OR(F7="",J7=0),"",F7/J7) | I7: =IF(H7="","",H7*7) | J7: =COUNTIFS('Daily Tracking'!$A$6:$A$735,">="&B7,'Daily Tracking'!$A$6:$A$735,"<="&C7,'Daily Tracking'!$B$6:$B$735,"<>") -> 0 | L7: =IF($F7="",NA(),$F7) -> #N/A
A8: =TEXT(B8,"mmm")&" "&YEAR(B8) -> nov 2026 | B8: =EOMONTH(B7,0)+1 -> 46327 | C8: =EOMONTH(B8,0) -> 46356 | D8: {=IF(J8=0,"",IFERROR(INDEX('Daily Tracking'!$B$6:$B$735,MATCH(1,INDEX((('Daily Tracking'!$A$6:$A$735>=B8)*('Daily Tracking'!$A$6:$A$735<=C8)*('Daily Tracking'!$B$6:$B$735<>"")),0),0)),""))} | E8: {=IF(J8=0,"",IFERROR(LOOKUP(2,1/(('Daily Tracking'!$A$6:$A$735>=B8)*('Daily Tracking'!$A$6:$A$735<=C8)*('Daily Tracking'!$B$6:$B$735<>"")),'Daily Tracking'!$B$6:$B$735),""))} | F8: =IF(OR(D8="",E8=""),"",D8-E8) | G8: =IF(F8="","",F8/D8) | H8: =IF(OR(F8="",J8=0),"",F8/J8) | I8: =IF(H8="","",H8*7) | J8: =COUNTIFS('Daily Tracking'!$A$6:$A$735,">="&B8,'Daily Tracking'!$A$6:$A$735,"<="&C8,'Daily Tracking'!$B$6:$B$735,"<>") -> 0 | L8: =IF($F8="",NA(),$F8) -> #N/A
A9: =TEXT(B9,"mmm")&" "&YEAR(B9) -> déc 2026 | B9: =EOMONTH(B8,0)+1 -> 46357 | C9: =EOMONTH(B9,0) -> 46387 | D9: {=IF(J9=0,"",IFERROR(INDEX('Daily Tracking'!$B$6:$B$735,MATCH(1,INDEX((('Daily Tracking'!$A$6:$A$735>=B9)*('Daily Tracking'!$A$6:$A$735<=C9)*('Daily Tracking'!$B$6:$B$735<>"")),0),0)),""))} | E9: {=IF(J9=0,"",IFERROR(LOOKUP(2,1/(('Daily Tracking'!$A$6:$A$735>=B9)*('Daily Tracking'!$A$6:$A$735<=C9)*('Daily Tracking'!$B$6:$B$735<>"")),'Daily Tracking'!$B$6:$B$735),""))} | F9: =IF(OR(D9="",E9=""),"",D9-E9) | G9: =IF(F9="","",F9/D9) | H9: =IF(OR(F9="",J9=0),"",F9/J9) | I9: =IF(H9="","",H9*7) | J9: =COUNTIFS('Daily Tracking'!$A$6:$A$735,">="&B9,'Daily Tracking'!$A$6:$A$735,"<="&C9,'Daily Tracking'!$B$6:$B$735,"<>") -> 0 | L9: =IF($F9="",NA(),$F9) -> #N/A
A10: =TEXT(B10,"mmm")&" "&YEAR(B10) -> janv 2027 | B10: =EOMONTH(B9,0)+1 -> 46388 | C10: =EOMONTH(B10,0) -> 46418 | D10: {=IF(J10=0,"",IFERROR(INDEX('Daily Tracking'!$B$6:$B$735,MATCH(1,INDEX((('Daily Tracking'!$A$6:$A$735>=B10)*('Daily Tracking'!$A$6:$A$735<=C10)*('Daily Tracking'!$B$6:$B$735<>"")),0),0)),""))} | E10: {=IF(J10=0,"",IFERROR(LOOKUP(2,1/(('Daily Tracking'!$A$6:$A$735>=B10)*('Daily Tracking'!$A$6:$A$735<=C10)*('Daily Tracking'!$B$6:$B$735<>"")),'Daily Tracking'!$B$6:$B$735),""))} | F10: =IF(OR(D10="",E10=""),"",D10-E10) | G10: =IF(F10="","",F10/D10) | H10: =IF(OR(F10="",J10=0),"",F10/J10) | I10: =IF(H10="","",H10*7) | J10: =COUNTIFS('Daily Tracking'!$A$6:$A$735,">="&B10,'Daily Tracking'!$A$6:$A$735,"<="&C10,'Daily Tracking'!$B$6:$B$735,"<>") -> 0 | L10: =IF($F10="",NA(),$F10) -> #N/A
A11: =TEXT(B11,"mmm")&" "&YEAR(B11) -> févr 2027 | B11: =EOMONTH(B10,0)+1 -> 46419 | C11: =EOMONTH(B11,0) -> 46446 | D11: {=IF(J11=0,"",IFERROR(INDEX('Daily Tracking'!$B$6:$B$735,MATCH(1,INDEX((('Daily Tracking'!$A$6:$A$735>=B11)*('Daily Tracking'!$A$6:$A$735<=C11)*('Daily Tracking'!$B$6:$B$735<>"")),0),0)),""))} | E11: {=IF(J11=0,"",IFERROR(LOOKUP(2,1/(('Daily Tracking'!$A$6:$A$735>=B11)*('Daily Tracking'!$A$6:$A$735<=C11)*('Daily Tracking'!$B$6:$B$735<>"")),'Daily Tracking'!$B$6:$B$735),""))} | F11: =IF(OR(D11="",E11=""),"",D11-E11) | G11: =IF(F11="","",F11/D11) | H11: =IF(OR(F11="",J11=0),"",F11/J11) | I11: =IF(H11="","",H11*7) | J11: =COUNTIFS('Daily Tracking'!$A$6:$A$735,">="&B11,'Daily Tracking'!$A$6:$A$735,"<="&C11,'Daily Tracking'!$B$6:$B$735,"<>") -> 0 | L11: =IF($F11="",NA(),$F11) -> #N/A
A12: =TEXT(B12,"mmm")&" "&YEAR(B12) -> mars 2027 | B12: =EOMONTH(B11,0)+1 -> 46447 | C12: =EOMONTH(B12,0) -> 46477 | D12: {=IF(J12=0,"",IFERROR(INDEX('Daily Tracking'!$B$6:$B$735,MATCH(1,INDEX((('Daily Tracking'!$A$6:$A$735>=B12)*('Daily Tracking'!$A$6:$A$735<=C12)*('Daily Tracking'!$B$6:$B$735<>"")),0),0)),""))} | E12: {=IF(J12=0,"",IFERROR(LOOKUP(2,1/(('Daily Tracking'!$A$6:$A$735>=B12)*('Daily Tracking'!$A$6:$A$735<=C12)*('Daily Tracking'!$B$6:$B$735<>"")),'Daily Tracking'!$B$6:$B$735),""))} | F12: =IF(OR(D12="",E12=""),"",D12-E12) | G12: =IF(F12="","",F12/D12) | H12: =IF(OR(F12="",J12=0),"",F12/J12) | I12: =IF(H12="","",H12*7) | J12: =COUNTIFS('Daily Tracking'!$A$6:$A$735,">="&B12,'Daily Tracking'!$A$6:$A$735,"<="&C12,'Daily Tracking'!$B$6:$B$735,"<>") -> 0 | L12: =IF($F12="",NA(),$F12) -> #N/A
A13: =TEXT(B13,"mmm")&" "&YEAR(B13) -> avr 2027 | B13: =EOMONTH(B12,0)+1 -> 46478 | C13: =EOMONTH(B13,0) -> 46507 | D13: {=IF(J13=0,"",IFERROR(INDEX('Daily Tracking'!$B$6:$B$735,MATCH(1,INDEX((('Daily Tracking'!$A$6:$A$735>=B13)*('Daily Tracking'!$A$6:$A$735<=C13)*('Daily Tracking'!$B$6:$B$735<>"")),0),0)),""))} | E13: {=IF(J13=0,"",IFERROR(LOOKUP(2,1/(('Daily Tracking'!$A$6:$A$735>=B13)*('Daily Tracking'!$A$6:$A$735<=C13)*('Daily Tracking'!$B$6:$B$735<>"")),'Daily Tracking'!$B$6:$B$735),""))} | F13: =IF(OR(D13="",E13=""),"",D13-E13) | G13: =IF(F13="","",F13/D13) | H13: =IF(OR(F13="",J13=0),"",F13/J13) | I13: =IF(H13="","",H13*7) | J13: =COUNTIFS('Daily Tracking'!$A$6:$A$735,">="&B13,'Daily Tracking'!$A$6:$A$735,"<="&C13,'Daily Tracking'!$B$6:$B$735,"<>") -> 0 | L13: =IF($F13="",NA(),$F13) -> #N/A
A14: =TEXT(B14,"mmm")&" "&YEAR(B14) -> mai 2027 | B14: =EOMONTH(B13,0)+1 -> 46508 | C14: =EOMONTH(B14,0) -> 46538 | D14: {=IF(J14=0,"",IFERROR(INDEX('Daily Tracking'!$B$6:$B$735,MATCH(1,INDEX((('Daily Tracking'!$A$6:$A$735>=B14)*('Daily Tracking'!$A$6:$A$735<=C14)*('Daily Tracking'!$B$6:$B$735<>"")),0),0)),""))} | E14: {=IF(J14=0,"",IFERROR(LOOKUP(2,1/(('Daily Tracking'!$A$6:$A$735>=B14)*('Daily Tracking'!$A$6:$A$735<=C14)*('Daily Tracking'!$B$6:$B$735<>"")),'Daily Tracking'!$B$6:$B$735),""))} | F14: =IF(OR(D14="",E14=""),"",D14-E14) | G14: =IF(F14="","",F14/D14) | H14: =IF(OR(F14="",J14=0),"",F14/J14) | I14: =IF(H14="","",H14*7) | J14: =COUNTIFS('Daily Tracking'!$A$6:$A$735,">="&B14,'Daily Tracking'!$A$6:$A$735,"<="&C14,'Daily Tracking'!$B$6:$B$735,"<>") -> 0 | L14: =IF($F14="",NA(),$F14) -> #N/A
A15: =TEXT(B15,"mmm")&" "&YEAR(B15) -> juin 2027 | B15: =EOMONTH(B14,0)+1 -> 46539 | C15: =EOMONTH(B15,0) -> 46568 | D15: {=IF(J15=0,"",IFERROR(INDEX('Daily Tracking'!$B$6:$B$735,MATCH(1,INDEX((('Daily Tracking'!$A$6:$A$735>=B15)*('Daily Tracking'!$A$6:$A$735<=C15)*('Daily Tracking'!$B$6:$B$735<>"")),0),0)),""))} | E15: {=IF(J15=0,"",IFERROR(LOOKUP(2,1/(('Daily Tracking'!$A$6:$A$735>=B15)*('Daily Tracking'!$A$6:$A$735<=C15)*('Daily Tracking'!$B$6:$B$735<>"")),'Daily Tracking'!$B$6:$B$735),""))} | F15: =IF(OR(D15="",E15=""),"",D15-E15) | G15: =IF(F15="","",F15/D15) | H15: =IF(OR(F15="",J15=0),"",F15/J15) | I15: =IF(H15="","",H15*7) | J15: =COUNTIFS('Daily Tracking'!$A$6:$A$735,">="&B15,'Daily Tracking'!$A$6:$A$735,"<="&C15,'Daily Tracking'!$B$6:$B$735,"<>") -> 0 | L15: =IF($F15="",NA(),$F15) -> #N/A
A16: =TEXT(B16,"mmm")&" "&YEAR(B16) -> juil 2027 | B16: =EOMONTH(B15,0)+1 -> 46569 | C16: =EOMONTH(B16,0) -> 46599 | D16: {=IF(J16=0,"",IFERROR(INDEX('Daily Tracking'!$B$6:$B$735,MATCH(1,INDEX((('Daily Tracking'!$A$6:$A$735>=B16)*('Daily Tracking'!$A$6:$A$735<=C16)*('Daily Tracking'!$B$6:$B$735<>"")),0),0)),""))} | E16: {=IF(J16=0,"",IFERROR(LOOKUP(2,1/(('Daily Tracking'!$A$6:$A$735>=B16)*('Daily Tracking'!$A$6:$A$735<=C16)*('Daily Tracking'!$B$6:$B$735<>"")),'Daily Tracking'!$B$6:$B$735),""))} | F16: =IF(OR(D16="",E16=""),"",D16-E16) | G16: =IF(F16="","",F16/D16) | H16: =IF(OR(F16="",J16=0),"",F16/J16) | I16: =IF(H16="","",H16*7) | J16: =COUNTIFS('Daily Tracking'!$A$6:$A$735,">="&B16,'Daily Tracking'!$A$6:$A$735,"<="&C16,'Daily Tracking'!$B$6:$B$735,"<>") -> 0 | L16: =IF($F16="",NA(),$F16) -> #N/A
A17: =TEXT(B17,"mmm")&" "&YEAR(B17) -> août 2027 | B17: =EOMONTH(B16,0)+1 -> 46600 | C17: =EOMONTH(B17,0) -> 46630 | D17: {=IF(J17=0,"",IFERROR(INDEX('Daily Tracking'!$B$6:$B$735,MATCH(1,INDEX((('Daily Tracking'!$A$6:$A$735>=B17)*('Daily Tracking'!$A$6:$A$735<=C17)*('Daily Tracking'!$B$6:$B$735<>"")),0),0)),""))} | E17: {=IF(J17=0,"",IFERROR(LOOKUP(2,1/(('Daily Tracking'!$A$6:$A$735>=B17)*('Daily Tracking'!$A$6:$A$735<=C17)*('Daily Tracking'!$B$6:$B$735<>"")),'Daily Tracking'!$B$6:$B$735),""))} | F17: =IF(OR(D17="",E17=""),"",D17-E17) | G17: =IF(F17="","",F17/D17) | H17: =IF(OR(F17="",J17=0),"",F17/J17) | I17: =IF(H17="","",H17*7) | J17: =COUNTIFS('Daily Tracking'!$A$6:$A$735,">="&B17,'Daily Tracking'!$A$6:$A$735,"<="&C17,'Daily Tracking'!$B$6:$B$735,"<>") -> 0 | L17: =IF($F17="",NA(),$F17) -> #N/A
A18: =TEXT(B18,"mmm")&" "&YEAR(B18) -> sept 2027 | B18: =EOMONTH(B17,0)+1 -> 46631 | C18: =EOMONTH(B18,0) -> 46660 | D18: {=IF(J18=0,"",IFERROR(INDEX('Daily Tracking'!$B$6:$B$735,MATCH(1,INDEX((('Daily Tracking'!$A$6:$A$735>=B18)*('Daily Tracking'!$A$6:$A$735<=C18)*('Daily Tracking'!$B$6:$B$735<>"")),0),0)),""))} | E18: {=IF(J18=0,"",IFERROR(LOOKUP(2,1/(('Daily Tracking'!$A$6:$A$735>=B18)*('Daily Tracking'!$A$6:$A$735<=C18)*('Daily Tracking'!$B$6:$B$735<>"")),'Daily Tracking'!$B$6:$B$735),""))} | F18: =IF(OR(D18="",E18=""),"",D18-E18) | G18: =IF(F18="","",F18/D18) | H18: =IF(OR(F18="",J18=0),"",F18/J18) | I18: =IF(H18="","",H18*7) | J18: =COUNTIFS('Daily Tracking'!$A$6:$A$735,">="&B18,'Daily Tracking'!$A$6:$A$735,"<="&C18,'Daily Tracking'!$B$6:$B$735,"<>") -> 0 | L18: =IF($F18="",NA(),$F18) -> #N/A
... A29: =TEXT(B29,"mmm")&" "&YEAR(B29) -> août 2028 | B29: =EOMONTH(B28,0)+1 -> 46966 | C29: =EOMONTH(B29,0) -> 46996 | D29: {=IF(J29=0,"",IFERROR(INDEX('Daily Tracking'!$B$6:$B$735,MATCH(1,INDEX((('Daily Tracking'!$A$6:$A$735>=B29)*('Daily Tracking'!$A$6:$A$735<=C29)*('Daily Tracking'!$B$6:$B$735<>"")),0),0)),""))} | E29: {=IF(J29=0,"",IFERROR(LOOKUP(2,1/(('Daily Tracking'!$A$6:$A$735>=B29)*('Daily Tracking'!$A$6:$A$735<=C29)*('Daily Tracking'!$B$6:$B$735<>"")),'Daily Tracking'!$B$6:$B$735),""))} | F29: =IF(OR(D29="",E29=""),"",D29-E29) | G29: =IF(F29="","",F29/D29) | H29: =IF(OR(F29="",J29=0),"",F29/J29) | I29: =IF(H29="","",H29*7) | J29: =COUNTIFS('Daily Tracking'!$A$6:$A$735,">="&B29,'Daily Tracking'!$A$6:$A$735,"<="&C29,'Daily Tracking'!$B$6:$B$735,"<>") -> 0 | L29: =IF($F29="",NA(),$F29) -> #N/A

Sheet Body Measurements
A1: BODY MEASUREMENTS
A2: Measure every 1–2 weeks. Change columns compare to your first entry.
A5: Date | B5: Waist (cm) | C5: Chest (cm) | D5: Arms (cm) | E5: Thighs (cm) | F5: Neck (cm) | G5: Δ Waist | H5: Δ Chest | I5: Δ Arms | J5: Δ Thighs | K5: Δ Neck
G6: =IF(OR(B6="",B$6=""),"",B6-B$6) | H6: =IF(OR(C6="",C$6=""),"",C6-C$6) | I6: =IF(OR(D6="",D$6=""),"",D6-D$6) | J6: =IF(OR(E6="",E$6=""),"",E6-E$6) | K6: =IF(OR(F6="",F$6=""),"",F6-F$6)
G7: =IF(OR(B7="",B$6=""),"",B7-B$6) | H7: =IF(OR(C7="",C$6=""),"",C7-C$6) | I7: =IF(OR(D7="",D$6=""),"",D7-D$6) | J7: =IF(OR(E7="",E$6=""),"",E7-E$6) | K7: =IF(OR(F7="",F$6=""),"",F7-F$6)
G8: =IF(OR(B8="",B$6=""),"",B8-B$6) | H8: =IF(OR(C8="",C$6=""),"",C8-C$6) | I8: =IF(OR(D8="",D$6=""),"",D8-D$6) | J8: =IF(OR(E8="",E$6=""),"",E8-E$6) | K8: =IF(OR(F8="",F$6=""),"",F8-F$6)
G9: =IF(OR(B9="",B$6=""),"",B9-B$6) | H9: =IF(OR(C9="",C$6=""),"",C9-C$6) | I9: =IF(OR(D9="",D$6=""),"",D9-D$6) | J9: =IF(OR(E9="",E$6=""),"",E9-E$6) | K9: =IF(OR(F9="",F$6=""),"",F9-F$6)
G10: =IF(OR(B10="",B$6=""),"",B10-B$6) | H10: =IF(OR(C10="",C$6=""),"",C10-C$6) | I10: =IF(OR(D10="",D$6=""),"",D10-D$6) | J10: =IF(OR(E10="",E$6=""),"",E10-E$6) | K10: =IF(OR(F10="",F$6=""),"",F10-F$6)
G11: =IF(OR(B11="",B$6=""),"",B11-B$6) | H11: =IF(OR(C11="",C$6=""),"",C11-C$6) | I11: =IF(OR(D11="",D$6=""),"",D11-D$6) | J11: =IF(OR(E11="",E$6=""),"",E11-E$6) | K11: =IF(OR(F11="",F$6=""),"",F11-F$6)
G12: =IF(OR(B12="",B$6=""),"",B12-B$6) | H12: =IF(OR(C12="",C$6=""),"",C12-C$6) | I12: =IF(OR(D12="",D$6=""),"",D12-D$6) | J12: =IF(OR(E12="",E$6=""),"",E12-E$6) | K12: =IF(OR(F12="",F$6=""),"",F12-F$6)
G13: =IF(OR(B13="",B$6=""),"",B13-B$6) | H13: =IF(OR(C13="",C$6=""),"",C13-C$6) | I13: =IF(OR(D13="",D$6=""),"",D13-D$6) | J13: =IF(OR(E13="",E$6=""),"",E13-E$6) | K13: =IF(OR(F13="",F$6=""),"",F13-F$6)
G14: =IF(OR(B14="",B$6=""),"",B14-B$6) | H14: =IF(OR(C14="",C$6=""),"",C14-C$6) | I14: =IF(OR(D14="",D$6=""),"",D14-D$6) | J14: =IF(OR(E14="",E$6=""),"",E14-E$6) | K14: =IF(OR(F14="",F$6=""),"",F14-F$6)
G15: =IF(OR(B15="",B$6=""),"",B15-B$6) | H15: =IF(OR(C15="",C$6=""),"",C15-C$6) | I15: =IF(OR(D15="",D$6=""),"",D15-D$6) | J15: =IF(OR(E15="",E$6=""),"",E15-E$6) | K15: =IF(OR(F15="",F$6=""),"",F15-F$6)
